import sys, random
import time
from mcpi import minecraft
mc = minecraft.Minecraft.create()

flat_world = input("Would you like to build a 4 chunk by 4 chunk flat world? y/n   ")
if flat_world == "y":
    x = list(range(-30, 34))
    z = list(range(-78, -14))
    print("ok, building your flat world")
    for row in z:
        for line in x:
            mc.setBlock(line, 45, row, 2)

    for row in z:
        for line in x:
            mc.setBlock(line, 44, row, 3)

    for row in z:
        for line in x:
            mc.setBlock(line, 43, row, 3)

    for row in z:
        for line in x:
            mc.setBlock(line, 42, row, 3)

    for row in z:
        for line in x:
            mc.setBlock(line, 41, row, 3)

    for row in z:
        for line in x:
            mc.setBlock(line, 40, row, 3)

    for row in z:
        for line in x:
            mc.setBlock(line, 46, row, 0)

    for row in z:
        for line in x:
            mc.setBlock(line, 47, row, 0)

    for row in z:
        for line in x:
            mc.setBlock(line, 48, row, 0)

    for row in z:
        for line in x:
            mc.setBlock(line, 49, row, 0)

    for row in z:
        for line in x:
            mc.setBlock(line, 50, row, 0)

    for row in z:
        for line in x:
            mc.setBlock(line, 51, row, 0)

    for row in z:
        for line in x:
            mc.setBlock(line, 52, row, 0)

    for row in z:
        for line in x:
            mc.setBlock(line, 53, row, 0)

    for row in z:
        for line in x:
            mc.setBlock(line, 54, row, 0)

    for row in z:
        for line in x:
            mc.setBlock(line, 55, row, 0)

    for row in z:
        for line in x:
            mc.setBlock(line, 56, row, 0)

    for row in z:
        for line in x:
            mc.setBlock(line, 57, row, 0)

    for row in z:
        for line in x:
            mc.setBlock(line, 58, row, 0)

    for row in z:
        for line in x:
            mc.setBlock(line, 59, row, 0)

    for row in z:
        for line in x:
            mc.setBlock(line, 60, row, 0)

    for row in z:
        for line in x:
            mc.setBlock(line, 61, row, 0)

    for row in z:
        for line in x:
            mc.setBlock(line, 62, row, 0)

    for row in z:
        for line in x:
            mc.setBlock(line, 63, row, 0)

    for row in z:
        for line in x:
            mc.setBlock(line, 64, row, 0)
    if flat_world == "n":
        print("ok")


mc.player.setTilePos(-1, 46, -47)
time.sleep(5)
mc.postToChat("Building Your House")
time.sleep(2)
mc.postToChat("Your House is 0% Done")
mc.setBlock(-3, 46, -45, 45)
time.sleep(.25)
mc.setBlock(-3, 46, -46, 45)
time.sleep(.25)
mc.setBlock(-3, 46, -48, 45)
time.sleep(.25)
mc.setBlock(-3, 46, -49, 45)
time.sleep(.25)
mc.setBlock(-3, 47, -45, 45)
time.sleep(.25)
mc.setBlock(-3, 47, -46, 45)
time.sleep(.25)
mc.setBlock(-3, 47, -48, 45)
time.sleep(.25)
mc.setBlock(-3, 47, -49, 45)
time.sleep(.25)
mc.setBlock(-3, 48, -45, 45)
time.sleep(.25)
mc.setBlock(-3, 48, -46, 45)
time.sleep(.25)
mc.setBlock(-3, 48, -47, 45)
time.sleep(.25)
mc.setBlock(-3, 48, -48, 45)
time.sleep(.25)
mc.setBlock(-3, 48, -49, 45)
time.sleep(.25)
mc.setBlock(-4, 46, -44, 45)
time.sleep(.25)
mc.setBlock(-4, 47, -44, 45)
time.sleep(.25)
mc.setBlock(-4, 48, -44, 45)
time.sleep(.25)
mc.setBlock(-5, 46, -44, 45)
time.sleep(.25)
mc.setBlock(-5, 48, -44, 45)
time.sleep(.25)
mc.setBlock(-6, 46, -44, 45)
time.sleep(.25)
mc.setBlock(-6, 47, -44, 45)
time.sleep(.25)
mc.setBlock(-6, 48, -44, 45)
time.sleep(.25)
mc.setBlock(-7, 46, -44, 45)
time.sleep(.25)
mc.setBlock(-7, 48, -44, 45)
time.sleep(.25)
mc.setBlock(-8, 46, -44, 45)
time.sleep(.25)
mc.setBlock(-8, 47, -44, 45)
mc.postToChat("Your House is 10% Done")
time.sleep(.25)
mc.setBlock(-8, 48, -44, 45)
time.sleep(.25)
mc.setBlock(-9, 46, -44, 45)
time.sleep(.25)
mc.setBlock(-9, 48, -44, 45)
time.sleep(.25)
mc.setBlock(-10, 46, -44, 45)
time.sleep(.25)
mc.setBlock(-10, 47, -44, 45)
time.sleep(.25)
mc.setBlock(-10, 48, -44, 45)
time.sleep(.25)
mc.setBlock(-11, 46, -45, 45)
time.sleep(.25)
mc.setBlock(-11, 47, -45, 45)
time.sleep(.25)
mc.setBlock(-11, 48, -45, 45)
time.sleep(.25)
mc.setBlock(-11, 46, -46, 45)
time.sleep(.25)
mc.setBlock(-11, 48, -46, 45)
time.sleep(.25)
mc.setBlock(-11, 46, -47, 45)
time.sleep(.25)
mc.setBlock(-11, 47, -47, 45)
time.sleep(.25)
mc.setBlock(-11, 48, -47, 45)
time.sleep(.25)
mc.setBlock(-11, 46, -48, 45)
time.sleep(.25)
mc.setBlock(-11, 48, -48, 45)
time.sleep(.25)
mc.setBlock(-11, 46, -49, 45)
time.sleep(.25)
mc.setBlock(-11, 47, -49, 45)
time.sleep(.25)
mc.setBlock(-11, 48, -49, 45)
time.sleep(.25)
mc.setBlock(-4, 46, -50, 45)
time.sleep(.25)
mc.setBlock(-4, 47, -50, 45)
time.sleep(.25)
mc.setBlock(-4, 48, -50, 45)
time.sleep(.25)
mc.setBlock(-5, 46, -50, 45)
time.sleep(.25)
mc.setBlock(-5, 48, -50, 45)
mc.postToChat("Your House Is 20% Done")
time.sleep(.25)
mc.setBlock(-6, 46, -50, 45)
time.sleep(.25)
mc.setBlock(-6, 47, -50, 45)
time.sleep(.25)
mc.setBlock(-6, 48, -50, 45)
time.sleep(.25)
mc.setBlock(-7, 46, -50, 45)
time.sleep(.25)
mc.setBlock(-7, 48, -50, 45)
time.sleep(.25)
mc.setBlock(-8, 46, -50, 45)
time.sleep(.25)
mc.setBlock(-8, 47, -50, 45)
time.sleep(.25)
mc.setBlock(-8, 48, -50, 45)
time.sleep(.25)
mc.setBlock(-9, 46, -50, 45)
time.sleep(.25)
mc.setBlock(-9, 48, -50, 45)
time.sleep(.25)
mc.setBlock(-10, 46, -50, 45)
time.sleep(.25)
mc.setBlock(-10, 47, -50, 45)
time.sleep(.25)
mc.setBlock(-10, 48, -50, 45)
time.sleep(.25)
mc.setBlock(-5, 47, -44, 20)
time.sleep(.25)
mc.setBlock(-7, 47, -44, 20)
time.sleep(.25)
mc.setBlock(-9, 47, -44, 20)
time.sleep(.25)
mc.setBlock(-11, 47, -46, 20)
time.sleep(.25)
mc.setBlock(-11, 47, -48, 20)
time.sleep(.25)
mc.setBlock(-5, 47, -50, 20)
time.sleep(.25)
mc.setBlock(-7, 47, -50, 20)
time.sleep(.25)
mc.setBlock(-9, 47, -50, 20)
time.sleep(.25)
mc.setBlock(-3, 45, -47, 1)
time.sleep(.25)
mc.setBlock(-4, 45, -45, 1)
time.sleep(.25)
mc.setBlock(-5, 45, -45, 1)
mc.postToChat("Your House Is 30% Done")
time.sleep(.25)
mc.setBlock(-6, 45, -45, 1)
time.sleep(.25)
mc.setBlock(-7, 45, -45, 1)
time.sleep(.25)
mc.setBlock(-8, 45, -45, 1)
time.sleep(.25)
mc.setBlock(-9, 45, -45, 1)
time.sleep(.25)
mc.setBlock(-10, 45, -45, 1)
time.sleep(.25)
mc.setBlock(-4, 45, -46, 1)
time.sleep(.25)
mc.setBlock(-5, 45, -46, 1)
time.sleep(.25)
mc.setBlock(-6, 45, -46, 1)
time.sleep(.25)
mc.setBlock(-7, 45, -46, 1)
time.sleep(.25)
mc.setBlock(-8, 45, -46, 1)
time.sleep(.25)
mc.setBlock(-9, 45, -46, 1)
time.sleep(.25)
mc.setBlock(-10, 45, -46, 1)
time.sleep(.25)
mc.setBlock(-4, 45, -47, 1)
time.sleep(.25)
mc.setBlock(-5, 45, -47, 1)
time.sleep(.25)
mc.setBlock(-6, 45, -47, 1)
time.sleep(.25)
mc.setBlock(-7, 45, -47, 1)
time.sleep(.25)
mc.setBlock(-8, 45, -47, 1)
time.sleep(.25)
mc.setBlock(-9, 45, -47, 1)
time.sleep(.25)
mc.setBlock(-10, 45, -47, 1)
time.sleep(.25)
mc.setBlock(-4, 45, -48, 1)
time.sleep(.25)
mc.setBlock(-5, 45, -48, 1)
time.sleep(.25)
mc.setBlock(-6, 45, -48, 1)
time.sleep(.25)
mc.setBlock(-7, 45, -48, 1)
mc.postToChat("Your House Is 40% Done")
time.sleep(.25)
mc.setBlock(-8, 45, -48, 1)
time.sleep(.25)
mc.setBlock(-9, 45, -48, 1)
time.sleep(.25)
mc.setBlock(-10, 45, -48, 1)
time.sleep(.25)
mc.setBlock(-4, 45, -49, 1)
time.sleep(.25)
mc.setBlock(-5, 45, -49, 1)
time.sleep(.25)
mc.setBlock(-6, 45, -49, 1)
time.sleep(.25)
mc.setBlock(-7, 45, -49, 1)
time.sleep(.25)
mc.setBlock(-8, 45, -49, 1)
time.sleep(.25)
mc.setBlock(-9, 45, -49, 1)
time.sleep(.25)
mc.setBlock(-10, 45, -49, 1)
time.sleep(.25)
mc.setBlock(-3, 46, -44, 5)
time.sleep(.25)
mc.setBlock(-3, 47, -44, 5)
time.sleep(.25)
mc.setBlock(-3, 48, -44, 5)
time.sleep(.25)
mc.setBlock(-3, 49, -44, 5)
time.sleep(.25)
mc.setBlock(-3, 46, -50, 5)
time.sleep(.25)
mc.setBlock(-3, 47, -50, 5)
time.sleep(.25)
mc.setBlock(-3, 48, -50, 5)
time.sleep(.25)
mc.setBlock(-3, 49, -50, 5)
time.sleep(.25)
mc.setBlock(-11, 46, -44, 5)
time.sleep(.25)
mc.setBlock(-11, 47, -44, 5)
time.sleep(.25)
mc.setBlock(-11, 48, -44, 5)
time.sleep(.25)
mc.setBlock(-11, 49, -44, 5)
time.sleep(.25)
mc.setBlock(-11, 46, -50, 5)
time.sleep(.25)
mc.setBlock(-11, 47, -50, 5)
mc.postToChat("Your House Is 50% Done")
time.sleep(.25)
mc.setBlock(-11, 48, -50, 5)
time.sleep(.25)
mc.setBlock(-11, 49, -50, 5)
time.sleep(.25)
mc.setBlock(-4, 49, -44, 1)
time.sleep(.25)
mc.setBlock(-5, 49, -44, 1)
time.sleep(.25)
mc.setBlock(-6, 49, -44, 1)
time.sleep(.25)
mc.setBlock(-7, 49, -44, 1)
time.sleep(.25)
mc.setBlock(-8, 49, -44, 1)
time.sleep(.25)
mc.setBlock(-9, 49, -44, 1)
time.sleep(.25)
mc.setBlock(-4, 49, -50, 1)
time.sleep(.25)
mc.setBlock(-5, 49, -50, 1)
time.sleep(.25)
mc.setBlock(-6, 49, -50, 1)
time.sleep(.25)
mc.setBlock(-7, 49, -50, 1)
time.sleep(.25)
mc.setBlock(-8, 49, -50, 1)
time.sleep(.25)
mc.setBlock(-9, 49, -50, 1)
time.sleep(.25)
mc.setBlock(-3, 49, -45, 1)
time.sleep(.25)
mc.setBlock(-3, 49, -46, 1)
time.sleep(.25)
mc.setBlock(-3, 49, -47, 1)
time.sleep(.25)
mc.setBlock(-3, 49, -48, 1)
time.sleep(.25)
mc.setBlock(-3, 49, -49, 1)
time.sleep(.25)
mc.setBlock(-10, 49, -44, 1)
time.sleep(.25)
mc.setBlock(-10, 49, -50, 1)
time.sleep(.25)
mc.setBlock(-11, 49, -45, 1)
time.sleep(.25)
mc.setBlock(-11, 49, -46, 1)
time.sleep(.25)
mc.setBlock(-11, 49, -47, 1)
mc.postToChat("Your House Is 60% Done")
time.sleep(.25)
mc.setBlock(-11, 49, -48, 1)
time.sleep(.25)
mc.setBlock(-11, 49, -49, 1)
time.sleep(.25)
mc.setBlock(-2, 49, -47, 5)
time.sleep(.25)
mc.setBlock(-2, 49, -46, 5)
time.sleep(.25)
mc.setBlock(-2, 49, -45, 5)
time.sleep(.25)
mc.setBlock(-2, 49, -44, 5)
time.sleep(.25)
mc.setBlock(-2, 49, -43, 5)
time.sleep(.25)
mc.setBlock(-3, 49, -43, 5)
time.sleep(.25)
mc.setBlock(-4, 49, -43, 5)
time.sleep(.25)
mc.setBlock(-5, 49, -43, 5)
time.sleep(.25)
mc.setBlock(-6, 49, -43, 5)
time.sleep(.25)
mc.setBlock(-7, 49, -43, 5)
time.sleep(.25)
mc.setBlock(-8, 49, -43, 5)
time.sleep(.25)
mc.setBlock(-9, 49, -43, 5)
time.sleep(.25)
mc.setBlock(-10, 49, -43, 5)
time.sleep(.25)
mc.setBlock(-11, 49, -43, 5)
time.sleep(.25)
mc.setBlock(-12, 49, -43, 5)
time.sleep(.25)
mc.setBlock(-12, 49, -44, 5)
time.sleep(.25)
mc.setBlock(-12, 49, -45, 5)
time.sleep(.25)
mc.setBlock(-12, 49, -46, 5)
time.sleep(.25)
mc.setBlock(-12, 49, -47, 5)
time.sleep(.25)
mc.setBlock(-12, 49, -48, 5)
time.sleep(.25)
mc.setBlock(-12, 49, -49, 5)
mc.postToChat("Your House Is 70% Done")
time.sleep(.25)
mc.setBlock(-12, 49, -50, 5)
time.sleep(.25)
mc.setBlock(-12, 49, -51, 5)
time.sleep(.25)
mc.setBlock(-11, 49, -51, 5)
time.sleep(.25)
mc.setBlock(-10, 49, -51, 5)
time.sleep(.25)
mc.setBlock(-9, 49, -51, 5)
time.sleep(.25)
mc.setBlock(-8, 49, -51, 5)
time.sleep(.25)
mc.setBlock(-7, 49, -51, 5)
time.sleep(.25)
mc.setBlock(-6, 49, -51, 5)
time.sleep(.25)
mc.setBlock(-5, 49, -51, 5)
time.sleep(.25)
mc.setBlock(-4, 49, -51, 5)
time.sleep(.25)
mc.setBlock(-3, 49, -51, 5)
time.sleep(.25)
mc.setBlock(-2, 49, -51, 5)
time.sleep(.25)
mc.setBlock(-2, 49, -50, 5)
time.sleep(.25)
mc.setBlock(-2, 49, -49, 5)
time.sleep(.25)
mc.setBlock(-2, 49, -48, 5)
time.sleep(.25)
mc.setBlock(-3, 50, -50, 5)
time.sleep(.25)
mc.setBlock(-3, 50, -49, 5)
time.sleep(.25)
mc.setBlock(-3, 50, -48, 5)
time.sleep(.25)
mc.setBlock(-3, 50, -47, 5)
time.sleep(.25)
mc.setBlock(-3, 50, -46, 5)
time.sleep(.25)
mc.setBlock(-3, 50, -45, 5)
time.sleep(.25)
mc.setBlock(-3, 50, -44, 5)
time.sleep(.25)
mc.setBlock(-4, 50, -44, 5)
time.sleep(.25)
mc.setBlock(-5, 50, -44, 5)
mc.postToChat("Your House Is 80% Done")
time.sleep(.25)
mc.setBlock(-6, 50, -44, 5)
time.sleep(.25)
mc.setBlock(-7, 50, -44, 5)
time.sleep(.25)
mc.setBlock(-8, 50, -44, 5)
time.sleep(.25)
mc.setBlock(-9, 50, -44, 5)
time.sleep(.25)
mc.setBlock(-10, 50, -44, 5)
time.sleep(.25)
mc.setBlock(-11, 50, -44, 5)
time.sleep(.25)
mc.setBlock(-11, 50, -45, 5)
time.sleep(.25)
mc.setBlock(-11, 50, -46, 5)
time.sleep(.25)
mc.setBlock(-11, 50, -47, 5)
time.sleep(.25)
mc.setBlock(-11, 50, -48, 5)
time.sleep(.25)
mc.setBlock(-11, 50, -49, 5)
time.sleep(.25)
mc.setBlock(-11, 50, -50, 5)
time.sleep(.25)
mc.setBlock(-10, 50, -50, 5)
time.sleep(.25)
mc.setBlock(-9, 50, -50, 5)
time.sleep(.25)
mc.setBlock(-8, 50, -50, 5)
time.sleep(.25)
mc.setBlock(-7, 50, -50, 5)
time.sleep(.25)
mc.setBlock(-6, 50, -50, 5)
time.sleep(.25)
mc.setBlock(-5, 50, -50, 5)
time.sleep(.25)
mc.setBlock(-4, 50, -50, 5)
time.sleep(.25)
mc.setBlock(-4, 51, -49, 5)
time.sleep(.25)
mc.setBlock(-4, 51, -48, 5)
time.sleep(.25)
mc.setBlock(-4, 51, -47, 5)
time.sleep(.25)
mc.setBlock(-4, 51, -46, 5)
mc.postToChat("Your House Is 90% Done")
time.sleep(.25)
mc.setBlock(-4, 51, -45, 5)
time.sleep(.25)
mc.setBlock(-5, 51, -45, 5)
time.sleep(.25)
mc.setBlock(-6, 51, -45, 5)
time.sleep(.25)
mc.setBlock(-7, 51, -45, 5)
time.sleep(.25)
mc.setBlock(-8, 51, -45, 5)
time.sleep(.25)
mc.setBlock(-9, 51, -45, 5)
time.sleep(.25)
mc.setBlock(-10, 51, -45, 5)
time.sleep(.25)
mc.setBlock(-10, 51, -46, 5)
time.sleep(.25)
mc.setBlock(-10, 51, -47, 5)
time.sleep(.25)
mc.setBlock(-10, 51, -48, 5)
time.sleep(.25)
mc.setBlock(-10, 51, -49, 5)
time.sleep(.25)
mc.setBlock(-9, 51, -49, 5)
time.sleep(.25)
mc.setBlock(-8, 51, -49, 5)
time.sleep(.25)
mc.setBlock(-7, 51, -49, 5)
time.sleep(.25)
mc.setBlock(-6, 51, -49, 5)
time.sleep(.25)
mc.setBlock(-5, 51, -49, 5)
time.sleep(.25)
mc.setBlock(-5, 52, -48, 5)
time.sleep(.25)
mc.setBlock(-5, 52, -47, 5)
time.sleep(.25)
mc.setBlock(-5, 52, -46, 5)
time.sleep(.25)
mc.setBlock(-6, 52, -46, 5)
time.sleep(.25)
mc.setBlock(-7, 52, -46, 5)
time.sleep(.25)
mc.setBlock(-8, 52, -46, 5)
time.sleep(.25)
mc.setBlock(-9, 52, -46, 5)
time.sleep(.25)
mc.setBlock(-9, 52, -47, 5)
time.sleep(.25)
mc.setBlock(-9, 52, -48, 5)
time.sleep(.25)
mc.setBlock(-8, 52, -48, 5)
time.sleep(.25)
mc.setBlock(-7, 52, -48, 5)
time.sleep(.25)
mc.setBlock(-6, 52, -48, 5)
time.sleep(.25)
mc.setBlock(-6, 53, -47, 5)
time.sleep(.25)
mc.setBlock(-7, 53, -47, 5)
time.sleep(.25)
mc.setBlock(-8, 53, -47, 5)
mc.postToChat("Your House Is 100% Done")

z_var = input()

if z_var == "tear down the house":
    time.sleep(5)
    mc.postToChat("Tearing Down The House")
    mc.postToChat("In 3")
    time.sleep(1.5)
    mc.postToChat("2")
    time.sleep(1.5)
    mc.postToChat("1")
    time.sleep(1)
    mc.setBlock(-3, 46, -45, 0)
    mc.setBlock(-3, 46, -46, 0)
    mc.setBlock(-3, 46, -48, 0)
    mc.setBlock(-3, 46, -49, 0)
    mc.setBlock(-3, 47, -45, 0)
    mc.setBlock(-3, 47, -46, 0)
    mc.setBlock(-3, 47, -48, 0)
    mc.setBlock(-3, 47, -49, 0)
    mc.setBlock(-3, 48, -45, 0)
    mc.setBlock(-3, 48, -46, 0)
    mc.setBlock(-3, 48, -47, 0)
    mc.setBlock(-3, 48, -48, 0)
    mc.setBlock(-3, 48, -49, 0)
    mc.setBlock(-4, 46, -44, 0)
    mc.setBlock(-4, 47, -44, 0)
    mc.setBlock(-4, 48, -44, 0)
    mc.setBlock(-5, 46, -44, 0)
    mc.setBlock(-5, 48, -44, 0)
    mc.setBlock(-6, 46, -44, 0)
    mc.setBlock(-6, 47, -44, 0)
    mc.setBlock(-6, 48, -44, 0)
    mc.setBlock(-7, 46, -44, 0)
    mc.setBlock(-7, 48, -44, 0)
    mc.setBlock(-8, 46, -44, 0)
    mc.setBlock(-8, 47, -44, 0)
    mc.setBlock(-8, 48, -44, 0)
    mc.setBlock(-9, 46, -44, 0)
    mc.setBlock(-9, 48, -44, 0)
    mc.setBlock(-10, 46, -44, 0)
    mc.setBlock(-10, 47, -44, 0)
    mc.setBlock(-10, 48, -44, 0)
    mc.setBlock(-11, 46, -45, 0)
    mc.setBlock(-11, 47, -45, 0)
    mc.setBlock(-11, 48, -45, 0)
    mc.setBlock(-11, 46, -46, 0)
    mc.setBlock(-11, 48, -46, 0)
    mc.setBlock(-11, 46, -47, 0)
    mc.setBlock(-11, 47, -47, 0)
    mc.setBlock(-11, 48, -47, 0)
    mc.setBlock(-11, 46, -48, 0)
    mc.setBlock(-11, 48, -48, 0)
    mc.setBlock(-11, 46, -49, 0)
    mc.setBlock(-11, 47, -49, 0)
    mc.setBlock(-11, 48, -49, 0)
    mc.setBlock(-4, 46, -50, 0)
    mc.setBlock(-4, 47, -50, 0)
    mc.setBlock(-4, 48, -50, 0)
    mc.setBlock(-5, 46, -50, 0)
    mc.setBlock(-5, 48, -50, 0)
    mc.setBlock(-6, 46, -50, 0)
    mc.setBlock(-6, 47, -50, 0)
    mc.setBlock(-6, 48, -50, 0)
    mc.setBlock(-7, 46, -50, 0)
    mc.setBlock(-7, 48, -50, 0)
    mc.setBlock(-8, 46, -50, 0)
    mc.setBlock(-8, 47, -50, 0)
    mc.setBlock(-8, 48, -50, 0)
    mc.setBlock(-9, 46, -50, 0)
    mc.setBlock(-9, 48, -50, 0)
    mc.setBlock(-10, 46, -50, 0)
    mc.setBlock(-10, 47, -50, 0)
    mc.setBlock(-10, 48, -50, 0)
    mc.setBlock(-5, 47, -44, 0)
    mc.setBlock(-7, 47, -44, 0)
    mc.setBlock(-9, 47, -44, 0)
    mc.setBlock(-11, 47, -46, 0)
    mc.setBlock(-11, 47, -48, 0)
    mc.setBlock(-5, 47, -50, 0)
    mc.setBlock(-7, 47, -50, 0)
    mc.setBlock(-9, 47, -50, 0)
    mc.setBlock(-3, 45, -47, 2)
    mc.setBlock(-4, 45, -45, 2)
    mc.setBlock(-5, 45, -45, 2)
    mc.setBlock(-6, 45, -45, 2)
    mc.setBlock(-7, 45, -45, 2)
    mc.setBlock(-8, 45, -45, 2)
    mc.setBlock(-9, 45, -45, 2)
    mc.setBlock(-10, 45, -45, 2)
    mc.setBlock(-4, 45, -46, 2)
    mc.setBlock(-5, 45, -46, 2)
    mc.setBlock(-6, 45, -46, 2)
    mc.setBlock(-7, 45, -46, 2)
    mc.setBlock(-8, 45, -46, 2)
    mc.setBlock(-9, 45, -46, 2)
    mc.setBlock(-10, 45, -46, 2)
    mc.setBlock(-4, 45, -47, 2)
    mc.setBlock(-5, 45, -47, 2)
    mc.setBlock(-6, 45, -47, 2)
    mc.setBlock(-7, 45, -47, 2)
    mc.setBlock(-8, 45, -47, 2)
    mc.setBlock(-9, 45, -47, 2)
    mc.setBlock(-10, 45, -47, 2)
    mc.setBlock(-4, 45, -48, 2)
    mc.setBlock(-5, 45, -48, 2)
    mc.setBlock(-6, 45, -48, 2)
    mc.setBlock(-7, 45, -48, 2)
    mc.setBlock(-8, 45, -48, 2)
    mc.setBlock(-9, 45, -48, 2)
    mc.setBlock(-10, 45, -48, 2)
    mc.setBlock(-4, 45, -49, 2)
    mc.setBlock(-5, 45, -49, 2)
    mc.setBlock(-6, 45, -49, 2)
    mc.setBlock(-7, 45, -49, 2)
    mc.setBlock(-8, 45, -49, 2)
    mc.setBlock(-9, 45, -49, 2)
    mc.setBlock(-10, 45, -49, 2)
    mc.setBlock(-3, 46, -44, 0)
    mc.setBlock(-3, 47, -44, 0)
    mc.setBlock(-3, 48, -44, 0)
    mc.setBlock(-3, 49, -44, 0)
    mc.setBlock(-3, 46, -50, 0)
    mc.setBlock(-3, 47, -50, 0)
    mc.setBlock(-3, 48, -50, 0)
    mc.setBlock(-3, 49, -50, 0)
    mc.setBlock(-11, 46, -44, 0)
    mc.setBlock(-11, 47, -44, 0)
    mc.setBlock(-11, 48, -44, 0)
    mc.setBlock(-11, 49, -44, 0)
    mc.setBlock(-11, 46, -50, 0)
    mc.setBlock(-11, 47, -50, 0)
    mc.setBlock(-11, 48, -50, 0)
    mc.setBlock(-11, 49, -50, 0)
    mc.setBlock(-4, 49, -44, 0)
    mc.setBlock(-5, 49, -44, 0)
    mc.setBlock(-6, 49, -44, 0)
    mc.setBlock(-7, 49, -44, 0)
    mc.setBlock(-8, 49, -44, 0)
    mc.setBlock(-9, 49, -44, 0)
    mc.setBlock(-4, 49, -50, 0)
    mc.setBlock(-5, 49, -50, 0)
    mc.setBlock(-6, 49, -50, 0)
    mc.setBlock(-7, 49, -50, 0)
    mc.setBlock(-8, 49, -50, 0)
    mc.setBlock(-9, 49, -50, 0)
    mc.setBlock(-3, 49, -45, 0)
    mc.setBlock(-3, 49, -46, 0)
    mc.setBlock(-3, 49, -47, 0)
    mc.setBlock(-3, 49, -48, 0)
    mc.setBlock(-3, 49, -49, 0)
    mc.setBlock(-10, 49, -44, 0)
    mc.setBlock(-10, 49, -50, 0)
    mc.setBlock(-11, 49, -45, 0)
    mc.setBlock(-11, 49, -46, 0)
    mc.setBlock(-11, 49, -47, 0)
    mc.setBlock(-11, 49, -48, 0)
    mc.setBlock(-11, 49, -49, 0)
    mc.setBlock(-2, 49, -47, 0)
    mc.setBlock(-2, 49, -46, 0)
    mc.setBlock(-2, 49, -45, 0)
    mc.setBlock(-2, 49, -44, 0)
    mc.setBlock(-2, 49, -43, 0)
    mc.setBlock(-3, 49, -43, 0)
    mc.setBlock(-4, 49, -43, 0)
    mc.setBlock(-5, 49, -43, 0)
    mc.setBlock(-6, 49, -43, 0)
    mc.setBlock(-7, 49, -43, 0)
    mc.setBlock(-8, 49, -43, 0)
    mc.setBlock(-9, 49, -43, 0)
    mc.setBlock(-10, 49, -43, 0)
    mc.setBlock(-11, 49, -43, 0)
    mc.setBlock(-12, 49, -43, 0)
    mc.setBlock(-12, 49, -44, 0)
    mc.setBlock(-12, 49, -45, 0)
    mc.setBlock(-12, 49, -46, 0)
    mc.setBlock(-12, 49, -47, 0)
    mc.setBlock(-12, 49, -48, 0)
    mc.setBlock(-12, 49, -49, 0)
    mc.setBlock(-12, 49, -50, 0)
    mc.setBlock(-12, 49, -51, 0)
    mc.setBlock(-11, 49, -51, 0)
    mc.setBlock(-10, 49, -51, 0)
    mc.setBlock(-9, 49, -51, 0)
    mc.setBlock(-8, 49, -51, 0)
    mc.setBlock(-7, 49, -51, 0)
    mc.setBlock(-6, 49, -51, 0)
    mc.setBlock(-5, 49, -51, 0)
    mc.setBlock(-4, 49, -51, 0)
    mc.setBlock(-3, 49, -51, 0)
    mc.setBlock(-2, 49, -51, 0)
    mc.setBlock(-2, 49, -50, 0)
    mc.setBlock(-2, 49, -49, 0)
    mc.setBlock(-2, 49, -48, 0)
    mc.setBlock(-3, 50, -50, 0)
    mc.setBlock(-3, 50, -49, 0)
    mc.setBlock(-3, 50, -48, 0)
    mc.setBlock(-3, 50, -47, 0)
    mc.setBlock(-3, 50, -46, 0)
    mc.setBlock(-3, 50, -45, 0)
    mc.setBlock(-3, 50, -44, 0)
    mc.setBlock(-4, 50, -44, 0)
    mc.setBlock(-5, 50, -44, 0)
    mc.setBlock(-6, 50, -44, 0)
    mc.setBlock(-7, 50, -44, 0)
    mc.setBlock(-8, 50, -44, 0)
    mc.setBlock(-9, 50, -44, 0)
    mc.setBlock(-10, 50, -44, 0)
    mc.setBlock(-11, 50, -44, 0)
    mc.setBlock(-11, 50, -45, 0)
    mc.setBlock(-11, 50, -46, 0)
    mc.setBlock(-11, 50, -47, 0)
    mc.setBlock(-11, 50, -48, 0)
    mc.setBlock(-11, 50, -49, 0)
    mc.setBlock(-11, 50, -50, 0)
    mc.setBlock(-10, 50, -50, 0)
    mc.setBlock(-9, 50, -50, 0)
    mc.setBlock(-8, 50, -50, 0)
    mc.setBlock(-7, 50, -50, 0)
    mc.setBlock(-6, 50, -50, 0)
    mc.setBlock(-5, 50, -50, 0)
    mc.setBlock(-4, 50, -50, 0)
    mc.setBlock(-4, 51, -49, 0)
    mc.setBlock(-4, 51, -48, 0)
    mc.setBlock(-4, 51, -47, 0)
    mc.setBlock(-4, 51, -46, 0)
    mc.setBlock(-4, 51, -45, 0)
    mc.setBlock(-5, 51, -45, 0)
    mc.setBlock(-6, 51, -45, 0)
    mc.setBlock(-7, 51, -45, 0)
    mc.setBlock(-8, 51, -45, 0)
    mc.setBlock(-9, 51, -45, 0)
    mc.setBlock(-10, 51, -45, 0)
    mc.setBlock(-10, 51, -46, 0)
    mc.setBlock(-10, 51, -47, 0)
    mc.setBlock(-10, 51, -48, 0)
    mc.setBlock(-10, 51, -49, 0)
    mc.setBlock(-9, 51, -49, 0)
    mc.setBlock(-8, 51, -49, 0)
    mc.setBlock(-7, 51, -49, 0)
    mc.setBlock(-6, 51, -49, 0)
    mc.setBlock(-5, 51, -49, 0)
    mc.setBlock(-5, 52, -48, 0)
    mc.setBlock(-5, 52, -47, 0)
    mc.setBlock(-5, 52, -46, 0)
    mc.setBlock(-6, 52, -46, 0)
    mc.setBlock(-7, 52, -46, 0)
    mc.setBlock(-8, 52, -46, 0)
    mc.setBlock(-9, 52, -46, 0)
    mc.setBlock(-9, 52, -47, 0)
    mc.setBlock(-9, 52, -48, 0)
    mc.setBlock(-8, 52, -48, 0)
    mc.setBlock(-7, 52, -48, 0)
    mc.setBlock(-6, 52, -48, 0)
    mc.setBlock(-6, 53, -47, 0)
    mc.setBlock(-7, 53, -47, 0)
    mc.setBlock(-8, 53, -47, 0)